Workbook
Name P_sec: '07_前提'!$C$5
Name B_adot: '07_前提'!$C$6
Name B_be: '07_前提'!$C$7
Name B_fe: '07_前提'!$C$8
Name B_cw: '07_前提'!$C$9
Name I_adot: '07_前提'!$C$10
Name I_be: '07_前提'!$C$11
Name I_fe: '07_前提'!$C$12
Name I_alb: '07_前提'!$C$13
Name H_alb: '07_前提'!$C$14
Name U_alb: '07_前提'!$C$15
Name Margin: '07_前提'!$C$16
Name SpPad: '07_前提'!$C$17
Name GraceNow: '07_前提'!$C$18
Name SpNow: '07_前提'!$C$19
Name I_alb_now: '07_前提'!$C$20
Name H_alb_now: '07_前提'!$C$21
Name U_alb_now: '07_前提'!$C$22
Name E_P: '07_前提'!$C$26
Name E_adot: '07_前提'!$C$27
Name E_be: '07_前提'!$C$28
Name E_fe: '07_前提'!$C$29

Sheet 00_読み方
A1: 読み方
A2: このブックは設計書です。灰色のセルだけを書き換えます。白い数値は式です。色は白・灰・黒だけです。
A4: このファイルで分かること
A5: ECS on Fargate の1つのタスクに、フロント、バックエンド、ADOT Collector、CloudWatch Agent を載せるときの、起動順とヘルスチェックと ALB の猶予の取り方です。
A6: いまの案は、猶予 300 秒、フロントとバックエンドの startPeriod 210 秒、コンテナ同士の依存なし、です。依存を HEALTHY で直列にすると、300 秒の時点でフロントがまだ準備中になり、タスクが止められ得ます。
A7: 結論の数値は「07_前提」の起動予算から計算しています。210 秒と 60 秒は、この環境で測った値ではなく、相談内容の予算です。実測に置き換えてください。
A8: シートの順
A9: 01_結論 … 先に採用値。ここだけ読んでも判断できます。
A10: 02_たとえ話 … 店、店長、案内人、郵便係のたとえ。仕組みの名前を覚える前に、時計が3つあることだけ掴みます。
A11: 03_歴史 … それぞれの機能が何年に、どの事故を止めるために入ったか。
A12: 04_設定できる範囲 … パラメータ名、場所、最小、最大、既定、今回の値。
A13: 05_三つの時計 … startPeriod、猶予、ALB のしきい値が、別々の瞬間から動く理由。
... A29: 取得後起算: P を 0 にします。コンテナが動き始めてから猶予の時計が動く場合の値です。公式文は「タスクが開始したあと」と書き、登録は ACTIVATING に含まれる、と別のページにあります。実測でどちらが早いかを見てください。

Sheet 01_結論
A1: 結論
A2: 210秒の予算のままフロントもバックエンドもHEALTHY待ちにすると、猶予300秒はフロントの準備完了より先に終わります。
A4: 判断
A5: 要件を両方守る（郵便係が準備できてから厨房、厨房が準備できてからレジ）ならパターンBです。猶予を延ばします。startPeriodは縮めません。
A6: レジは先に開けて、厨房のAPIはアプリがリトライするならパターンCです。郵便係と厨房のHEALTHY待ちは残せます。
A7: 店を2軒に分けるならパターンDです。レジの時計と厨房の時計が別々になります。
A8: startPeriodを210より小さくしても、アプリの起動は短くなりません。準備より短い免責は、コンテナをUNHEALTHYにして依存を失敗させます。
A9: CloudWatch Agent は依存が無いので直列には入りません。ADOTはHEALTHY待ちの先頭に入ります。イメージ取得は全員の前に1回だけ入ります。
A11: 採用する猶予（07_前提から再計算）
A12: パターン | B12: 依存 | C12: 安全側の最低 | D12: 安全側の推奨 | E12: 取得後の推奨 | F12: 300秒との関係
A13: A 並列（現行の形） | B13: フロントとバックの間は無し | C13: ='08_計算'!C21 | D13: ='08_計算'!C22 | E13: ='08_計算'!D22 | F13: 推奨ALB（間隔10、健全2）に変えた場合
A14: A 並列＋現行ALB | B14: 依存なし。ALBは既定のまま | C14: ='08_計算'!C25 | D14: ='08_計算'!C26 | E14: ='08_計算'!D26 | F14: 間隔30、健全5のまま、起動中に故障札になる場合
A15: B 全直列 | B15: ADOT HEALTHY → BE HEALTHY → FE | C15: ='08_計算'!C34 | D15: ='08_計算'!C35 | E15: ='08_計算'!D35 | F15: 相談の依存を全部入れる場合。300秒では不足
A16: B 全直列＋現行ALB | B16: 同じ直列。ALBは既定 | C16: ='08_計算'!C37 | D16: ='08_計算'!C38 | E16: ='08_計算'!D38 | F16: 最も長い。既定ALBの復帰が上乗せされる
A17: C 折衷 | B17: BEだけADOTを待つ。FEは待たない | C17: ='08_計算'!C44 | D17: ='08_計算'!C45 | E17: ='08_計算'!D45 | F17: トレースは守る。フロントはAPIをリトライする
A18: D フロントサービス | B18: サービス分割。フロント単独 | C18: ='08_計算'!C47 | D18: ='08_計算'!C48 | E18: ='08_計算'!D48 | F18: フロントの時計だけ
A19: D バックエンドサービス | B19: サービス分割。内部ALBあり | C19: ='08_計算'!C51 | D19: ='08_計算'!C52 | E19: ='08_計算'!D52 | F19: ALBが無ければ猶予は主役にならない
A20: E 短い起動の例 | B20: 直列。例の入力 | C20: ='08_計算'!C58 | D20: ='08_計算'!C59 | E20: ='08_計算'!D59 | F20: 実測が短ければ直列でも300秒に収まる
A22: コンテナに書く値（本番予算）
A23: コンテナ | B23: essential | C23: dependsOn | D23: startPeriod | E23: interval / timeout / retries | F23: startTimeout
A24: ADOT Collector | B24: true | C24: なし（先頭） | D24: ='08_計算'!C10 | E24: 5 / 2 / 5 | F24: ='08_計算'!C14
A25: バックエンド | B25: true | C25: ADOT が HEALTHY | D25: ='08_計算'!C11 | E25: 10 / 5 / 3 | F25: 空欄（待ちが120秒を超える）
A26: フロントエンド | B26: true | C26: パターンBならバックエンドが HEALTHY。Cなら無し | D26: ='08_計算'!C12 | E26: 10 / 5 / 3 | F26: 空欄
A27: CloudWatch Agent | B27: false | C27: なし | D27: ='08_計算'!C13 | E27: 30 / 5 / 3 | F27: 空欄
A29: ALBターゲットグループ（フロントのポート）: 間隔10秒、タイムアウト5秒、健全しきい値2、不健全しきい値3、成功コード200、パスは準備完了URL、スロースタート0。登録解除の遅延300秒は閉店時の設定なので、この起動問題の解ではありません。

Sheet 02_たとえ話
A1: 02_たとえ話
A2: 名前を覚える前に、時計が3つあることだけ見ます。
A4: 1軒の店
A5: 1つのタスクは、1軒の店です。同じ建物の中に、レジ（フロント）、厨房（バックエンド）、郵便係（ADOT Collector）、記録係（CloudWatch Agent）がいます。
A6: 通りの案内人（ALB）は、レジの電気が点いているかをノックして確かめます。点いていなければ、客をその店に案内しません。店長（ECSのスケジューラ）は、案内人が「閉まっている」と言い続けると、猶予のあと店を畳んで、新しい店を出します。
A7: 郵便係は、厨房が出したトレースという手紙を受け取って、外へ送ります。郵便受けの準備ができる前に投げられた手紙は、床に落ちて消えます。記録係は温度のメモを取ります。記録係が休んでも、店は開けたままにできます。
A8: 体温計と、案内人のノック
A9: 各人の体温計が、コンテナヘルスチェックです。終了コード0なら元気、0以外なら失敗です。案内人のノックは、外からレジの扉を叩くALBのヘルスチェックです。体温計は建物の中、ノックは通り側です。
A10: 体温計の成功は1回で「起きた」になります。retries は、何回連続で失敗したら「病気」にするか、です。案内人の健全しきい値は、一度「故障」の札がかかった店を、何回連続で成功したら案内先に戻すか、です。新しい店の最初の成功は1回で足ります。起動が長くて先に故障札がかかると、そこから戻すのにしきい値の回数がいります。
A11: 寝ぼけ免責と、店長の見逃し
A12: startPeriod は、その人の寝ぼけ免責です。免責のあいだの失敗は、病気の回数に数えません。免責が終わるまで起きられない、という意味ではありません。早く検査に受かれば、その瞬間に次の人を起こせます。
A13: 猶予（healthCheckGracePeriodSeconds）は、店長が赤札を見ても店を畳まない時間です。案内人は最初の瞬間からノックしています。300秒経ってノックを始めるのではありません。300秒で終わるのは、見逃しです。
... A20: 荷物（コンテナイメージ）の受け取りは、4人が順番に受け取るのではありません。開店前に、まとめて1回です。この受け取りが店長の時計に含まれるかは、登録の時刻で変わります。含まれる仮定が安全側、含まれない仮定が取得後起算です。

Sheet 03_歴史
A1: 03_歴史
A2: それぞれのつまみは、別の事故を止めるために、別の年に入りました。
A4: 案内人が先にいた
A5: 2009年、Classic Load Balancer が案内人として登場しました。サーバーが応答するかを見て、死んでいるサーバーへ客を送らないためです。コンテナはまだ主流ではありません。
A6: 2013年に Docker が広まり、2014年11月に Amazon ECS のプレビュー、2015年4月9日に一般提供が始まりました。箱をたくさん並べる係がAWS側にできた、という段階です。
A7: 体温計
A8: 2016年7月の Docker 1.12 で、箱の中に HEALTHCHECK を書けるようになりました。終了コードで元気かどうかを見る、いまのコンテナ検査の元です。
A9: 2017年5月の Docker Engine 17.05 で、health start period が入りました。Java のように起動が遅い箱が、起動中の失敗だけで「病気」になり、すぐ作り直される事故を止めるためです。ECSの startPeriod はこの考え方を、0〜300秒の範囲でタスク定義に置いたものです。
A10: 案内人が扉を区別できるようになった
A11: 2016年8月11日に Application Load Balancer が登場し、パスとターゲットグループで、どの扉を叩くかを指定できるようになりました。ECSのサービスは、このターゲットグループへタスクを登録します。
A12: 登録された直後からノックは始まります。アプリがまだ listen していないと接続は拒否され、不健全しきい値まで失敗すると故障札になります。
A13: 店長の見逃し
... A31: 画面の隣同士が同じ300秒なので、起動の見逃しと、閉店後の接続排出と、免責の上限が、1つの「グレースタイムアウト」に見えやすくなっています。この設計書では、それらを別の行に分けています。

Sheet 04_設定できる範囲
A1: 設定できる範囲
A2: 2026-10-07 に公式APIとユーザーガイドで確認した範囲です。製品の更新で変わるので、変更前にもう一度コンソールのエラーメッセージを見てください。
A4: 場所 | B4: パラメータ | C4: 指定できる範囲 | D4: 既定 | E4: 今回の値 | F4: 時計の起点 | G4: 実際に何が起きるか
A5: ECSサービス | B5: healthCheckGracePeriodSeconds | C5: 0 〜 2,147,483,647 秒 | D5: 0 | E5: パターン別。Bの安全側は計算シート | F5: タスク開始後 | G5: ELB、VPC Lattice、コンテナ検査の異常を、スケジューラが無視する。検査は止まらない。
A6: コンテナ | B6: healthCheck.command | C6: 先頭が CMD または CMD-SHELL | D6: 必須（検査を書くとき） | E6: ADOTは CMD /healthcheck | F6: そのコンテナ | G6: 終了コード0が成功。コマンドはイメージの中に存在する必要がある。
A7: コンテナ | B7: healthCheck.interval | C7: 5 〜 300 秒 | D7: 30 | E7: ADOT 5、アプリ 10、CW 30 | F7: プロセス開始 | G7: 最初の検査も、開始からこの秒数後。以降もこの間隔。
A8: コンテナ | B8: healthCheck.timeout | C8: 2 〜 60 秒 | D8: 5 | E8: ADOT 2、他 5 | F8: その検査 | G8: この秒でコマンドが終わらなければ失敗。interval より短くする規則は、コンテナ検査には無い。
A9: コンテナ | B9: healthCheck.retries | C9: 1 〜 10 | D9: 3 | E9: ADOT 5、他 3 | F9: 免責のあと | G9: 連続失敗がこの回数で UNHEALTHY。HEALTHYになるのに必要な成功回数は1。
A10: コンテナ | B10: healthCheck.startPeriod | C10: 0 〜 300 秒 | D10: オフ（0） | E10: 計算シートの sp_* | F10: そのコンテナのプロセス開始 | G10: この間の失敗は retries に数えない。成功した瞬間に HEALTHY。その後の失敗は数える。
A11: コンテナ | B11: dependsOn.condition | C11: START / COMPLETE / SUCCESS / HEALTHY | D11: なし | E11: HEALTHY | F11: 起動時だけ | G11: HEALTHYは相手の検査成功を待つ。COMPLETEとSUCCESSは essential には不可。
A12: コンテナ | B12: startTimeout | C12: 書くなら Fargate は 2 〜 120 秒 | D12: 未指定時の秒数は同じページに無い | E12: ADOTは計算値。バックは空欄 | F12: 依存の解決 | G12: 待たれているコンテナに書く、と公式例は説明している。時間内に条件を満たさなければ待つ側は起動しない。タスクは STOPPED。
A13: コンテナ | B13: stopTimeout | C13: Fargate 最大 120 秒 | D13: 30 | E13: 今回は既定のままでよい | F13: 停止シグナルのあと | G13: 自分で終わらないプロセスを強制停止するまで。依存の終了順とは別。
A14: コンテナ | B14: essential | C14: true / false | D14: true | E14: ADOTとアプリは true、CWは false | F14: タスクの一生 | G14: essential の終了、または検査UNHEALTHYが、タスク停止の材料になる。false はタスクヘルスに入らない。
A15: ALBターゲットグループ | B15: HealthCheckIntervalSeconds | C15: 5 〜 300 秒 | D15: instance/ip は 30 | E15: 10 | F15: 登録後 | G15: 各ターゲットへのノック間隔。
... A25: 参考 | B25: EC2 Auto Scaling の猶予 | C25: グループ設定 | D25: コンソール作成時 300 秒、API作成時 0 秒が多い | E25: 今回の対象外 | F25: インスタンスの InService 後 | G25: ECSサービスの healthCheckGracePeriodSeconds とは別物。

Sheet 05_三つの時計
A1: 05_三つの時計
A2: 同じ「秒」でも、ゼロ地点が違います。
A4: 時計1 コンテナの startPeriod
A5: ゼロ地点は、そのコンテナのプロセスが開始した瞬間です。タスクが PENDING になった瞬間ではありません。イメージ取得のあいだは、まだこの時計は動いていません。
A6: 動いているあいだ、検査は止まりません。失敗を病気の回数に入れないだけです。1回でも成功すると HEALTHY になり、依存で待っている次のコンテナが起動します。startPeriod の残り時間は待ちません。
A7: 上限は300秒です。起動が300秒を超えるコンテナは、この免責だけでは覆いきれません。免責が終わったあと、retries × interval の失敗で UNHEALTHY になります。
A8: 時計2 サービスの猶予
A9: ゼロ地点は、公式には「タスクが開始したあと」です。別の説明では、イメージ取得、コンテナ作成、ネットワーク、ターゲットグループへの登録が ACTIVATING に含まれます。登録が RUNNING より前なら、ノックは猶予の消費と同時か、それより前から始まります。
A10: この時計はタスクに1つです。フロント専用の猶予はありません。直列にすると、ADOTの起動、バックエンドの起動、フロントの起動が、同じ300秒の中で順番に消費されます。
A11: 猶予が終わった時点でターゲットがまだ unhealthy なら、スケジューラはそのタスクを置き換えの対象にします。起動が間に合えば、猶予は何もしません。長くしすぎると、本当に壊れた起動の置き換えが遅れます。
A12: 例外があります。実行中タスクが desired より多いとき、猶予中でも unhealthy のタスクが desired へ戻すために止まることがあります。ロール中の重なりで起きます。
A13: 時計3 ALBの間隔としきい値
... A22: フロントの startPeriod は、フロントのプロセスが始まってから動きます。直列の待ちで既に過ぎた秒数は、フロントの免責を消費しません。消費するのは店長の猶予の方です。

Sheet 06_動作原理
A1: 06_動作原理
A2: 依存、essential、13133、localhost、タスクが止まる条件。
A4: タスクの状態と登録
A5: Fargate では、イメージ取得はコンテナのプロセス開始より前です。APIのライフサイクル説明では、ACTIVATING でイメージ取得、コンテナ作成、ネットワーク、ロードバランサーへの登録、サービスディスカバリが行われ、RUNNING でタスクが仕事をします。
A6: 猶予の文章は「タスクが開始したあと」です。登録の文章は ACTIVATING に登録を含みます。この2つが同じ秒とは書かれていません。だからブックは、取得を含む安全側と、含まない取得後起算の両方を出します。
A7: 検査の状態
A8: コンテナは HEALTHY、UNHEALTHY、UNKNOWN です。startPeriod 中でまだ成功していない状態は UNKNOWN 側に見えます。成功で HEALTHY。免責後に retries まで失敗すると UNHEALTHY。
A9: タスクヘルスは、essential かつ検査コマンドがあるコンテナだけで決まります。1つでも UNHEALTHY ならタスクは UNHEALTHY。UNHEALTHY が無く UNKNOWN があればタスクは UNKNOWN。対象が全部 HEALTHY ならタスクは HEALTHY。
A10: CloudWatch Agent を essential false にすると、その UNHEALTHY はタスクヘルスに入りません。ADOT を essential true にすると、コレクタの UNHEALTHY はタスクの UNHEALTHY です。猶予のあと、サービスはタスクを置き換えます。
A11: 手動で RunTask したタスクは、ヘルスが悪くてもライフサイクルを続けます。サービスに属しているタスクは、UNHEALTHY になると止められ、代わりが起動されます。
A12: HEALTHY 依存の解け方
A13: 相手のコンテナに healthCheck が必要です。検査が1回成功すると解けます。startPeriod の満了は条件ではありません。
... A29: desiredCount が1で、起動中に唯一のターゲットが unhealthy になると、ALBは全ターゲット故障時のフェイルオープンで、準備中のタスクへリクエストを送ることがあります。本番は2タスク以上か、古い healthy を残すデプロイ設定にします。

Sheet 07_前提
A1: 前提（灰色のセルだけ入力）
A2: 210秒と60秒は相談時の予算です。DescribeTasks の時刻と、アプリが200を返し始めた時刻で置き換えてください。
A4: 記号 | B4: 意味 | C4: 入力値 | D4: 単位 | E4: 下限 | F4: 上限 | G4: この予算の意味 | H4: 測り方
A5: P_sec | B5: P イメージ取得など先行時間 | C5: 60 | D5: 秒 | E5: 0 | F5: 600 | G5: 全イメージの取得と、タスクのネットワーク準備。チェーンの中では1回だけ先頭に足す。 | H5: DescribeTasks の pullStartedAt と pullStoppedAt の差。大きいイメージの日を使う。
A6: B_adot | B6: B_adot ADOTが応答できるまでの時間 | C6: 30 | D6: 秒 | E6: 1 | F6: 600 | G6: ADOTのプロセス開始から、13133の検査が成功する準備ができるまで。Go製コレクタは通常これより短い。遅い日の予算。 | H6: コレクタのログでパイプライン開始が出た時刻。コンテナの started から測る。
A7: B_be | B7: B_be バックエンドの準備完了 | C7: 210 | D7: 秒 | E7: 1 | F7: 600 | G7: バックエンドのプロセス開始から、準備完了の検査が成功するまで。startPeriod 210秒の根拠として置いた予算。 | H7: アプリログの listen と、コンテナ検査の初回成功。サイドカーが同じタスクにいる状態で測る。
A8: B_fe | B8: B_fe フロントの準備完了 | C8: 210 | D8: 秒 | E8: 1 | F8: 600 | G8: フロントのプロセス開始から、ALBと同じ準備完了パスが200を返すまで。 | H8: フロントのログと、ALBターゲットが成功を返し始めた時刻。
A9: B_cw | B9: B_cw CloudWatch Agentの起動 | C9: 30 | D9: 秒 | E9: 1 | F9: 600 | G9: プロセス検査が成功するまでの予算。依存が無いので直列時間には入らない。 | H9: エージェントのプロセスが現れた時刻。
A10: I_adot | B10: I_adot ADOTの検査間隔 | C10: 5 | D10: 秒 | E10: 5 | F10: 300 | G10: コンテナヘルスチェックの interval。最小5秒。短いほど HEALTHY の検出が速い。 | H10: タスク定義の healthCheck.interval。
A11: I_be | B11: I_be バックエンドの検査間隔 | C11: 10 | D11: 秒 | E11: 5 | F11: 300 | G11: 準備完了の検出遅れの上限にほぼ等しい。 | H11: タスク定義。
A12: I_fe | B12: I_fe フロントの検査間隔 | C12: 10 | D12: 秒 | E12: 5 | F12: 300 | G12: コンテナ側の検査。ALBの間隔とは別のつまみ。 | H12: タスク定義。
A13: I_alb | B13: I_alb 推奨ALBの間隔 | C13: 10 | D13: 秒 | E13: 5 | F13: 300 | G13: ターゲットグループの HealthCheckIntervalSeconds。推奨値。 | H13: ターゲットグループの属性。
A14: H_alb | B14: H_alb 推奨ALBの健全しきい値 | C14: 2 | D14: 回 | E14: 2 | F14: 10 | G14: unhealthy から healthy へ戻す連続成功回数。初期登録のままならこの回数は使われない。 | H14: HealthyThresholdCount。最小2。
A15: U_alb | B15: U_alb 推奨ALBの不健全しきい値 | C15: 3 | D15: 回 | E15: 2 | F15: 10 | G15: 連続失敗がこの回数で unhealthy。起動がこの回数×間隔を超えると、復帰に健全しきい値が必要になる。 | H15: UnhealthyThresholdCount。
A16: Margin | B16: 余白 | C16: 60 | D16: 秒 | E16: 0 | F16: 300 | G16: 検査のずれ、スケジューラの遅れ、コールドスタートのばらつき。 | H16: デプロイを数回見て、計算との差が余白を超えたら増やす。
... A22: U_alb_now | B22: 現行ALBの不健全しきい値（不明なら既定） | C22: 2 | D22: 回 | E22: 2 | F22: 10 | G22: 既定は2。30秒間隔なら約60秒で起動中のターゲットがunhealthyになる。 | H22: ターゲットグループ。
A24: 参考入力: 実測が短かった場合の例（パターンE）。上の本番予算とは別です。
A25: 記号 | B25: 意味 | C25: 入力値 | D25: 単位 | E25: 下限 | F25: 上限 | G25: この予算の意味 | H25: 測り方
A26: E_P | B26: 例 P | C26: 20 | D26: 秒 | E26: 0 | F26: 600 | G26: 取得が短い日。 | H26: 例。
A27: E_adot | B27: 例 ADOT準備 | C27: 10 | D27: 秒 | E27: 1 | F27: 600 | G27: コレクタが速い日。 | H27: 例。
A28: E_be | B28: 例 バックエンド準備 | C28: 60 | D28: 秒 | E28: 1 | F28: 600 | G28: バックエンドが1分で準備完了する日。 | H28: 例。
A29: E_fe | B29: 例 フロント準備 | C29: 45 | D29: 秒 | E29: 1 | F29: 600 | G29: フロントが45秒で準備完了する日。 | H29: 例。
A31: 本番の判断は上のブロックです。下の例は「起動が本当に短ければ直列依存でも猶予は短い」ことを示す教材です。間隔としきい値は上の推奨ALBを共用します。

Sheet 08_計算
A1: 計算
A2: C列は安全側（Pを含む）。D列は取得後起算（P=0）。どちらも07_前提を参照します。
A4: キー | B4: 意味 | C4: 安全側（秒） | D4: 取得後起算（秒） | E4: 式の意味
A5: adot_h | B5: ADOTがHEALTHYになる最悪（プロセス開始から） | C5: =B_adot+I_adot | D5: =B_adot+I_adot | E5: 準備完了＋最大1間隔。最初の検査は間隔秒後。
A6: be_h | B6: バックエンドがHEALTHYになる最悪（プロセス開始から） | C6: =B_be+I_be | D6: =B_be+I_be | E6: 成功1回でHEALTHY。しきい値回数は不要。
A7: fe_h | B7: フロントコンテナがHEALTHYになる最悪（プロセス開始から） | C7: =B_fe+I_fe | D7: =B_fe+I_fe | E7: コンテナ検査は成功1回。ALBのしきい値とは別。
A8: flip | B8: 推奨ALBがunhealthyにするまでの失敗時間 | C8: =U_alb*I_alb | D8: =U_alb*I_alb | E8: 登録後、この秒数ぶん失敗が続くと故障札になる。
A9: flip_now | B9: 現行ALBがunhealthyにするまでの失敗時間 | C9: =U_alb_now*I_alb_now | D9: =U_alb_now*I_alb_now | E9: 既定なら2×30=60秒。
A10: sp_adot | B10: ADOTのstartPeriod | C10: =MIN(300,B_adot+SpPad) | D10: =MIN(300,B_adot+SpPad) | E10: 上限300。失敗の免責。成功は待たない。
A11: sp_be | B11: バックエンドのstartPeriod | C11: =MIN(300,B_be+SpPad) | D11: =MIN(300,B_be+SpPad) | E11: 210+30=240。上限内。
A12: sp_fe | B12: フロントのstartPeriod | C12: =MIN(300,B_fe+SpPad) | D12: =MIN(300,B_fe+SpPad) | E12: 210+30=240。
A13: sp_cw | B13: CloudWatch AgentのstartPeriod | C13: =MIN(300,B_cw+SpPad) | D13: =MIN(300,B_cw+SpPad) | E13: 直列時間には入らない。
A14: st_adot | B14: ADOTのstartTimeout採用値 | C14: =MIN(120,MAX(2,CEILING(B_adot+I_adot+SpPad,30))) | D14: =MIN(120,MAX(2,CEILING(B_adot+I_adot+SpPad,30))) | E14: Fargateの指定範囲は2〜120。90秒前後になる。
A15: be_wait | B15: バックエンドHEALTHYを待つ秒数 | C15: =B_be+I_be | D15: =B_be+I_be | E15: この値が120を超えるとstartTimeoutは書けない。
A16: パターンA 依存なし。全員が同時にプロセスを開始する。
A17: a_ready | B17: フロントが応答できる時刻 | C17: =P_sec+B_fe | D17: =B_fe | E17: 登録を時計の起点とみなす。安全側はPのあと。
A18: a_extra | B18: ALBがhealthyになるまでの追加 | C18: =IF(C17<=C8,I_alb,I_alb*H_alb) | D18: =IF(D17<=D8,I_alb,I_alb*H_alb) | E18: 準備完了が故障札より前なら追加は1間隔。超えたら間隔×健全しきい値。
A19: a_alb | B19: ALBがhealthyになる最悪 | C19: =C17+C18 | D19: =D17+D18 | E19: 猶予はこの時刻を超える。
A20: a_be | B20: バックエンドコンテナHEALTHY | C20: =P_sec+B_be+I_be | D20: =B_be+I_be | E20: essential なので、猶予後にUNHEALTHYだとタスクが止まる。
A21: a_gmin | B21: Aの最低猶予 | C21: =MAX(C19,C20,P_sec+B_fe+I_fe,P_sec+B_adot+I_adot) | D21: =MAX(D19,D20,B_fe+I_fe,B_adot+I_adot) | E21: ALBと、各essentialコンテナのHEALTHYの、遅い方。
A22: a_grec | B22: Aの推奨猶予 | C22: =CEILING(C21+Margin,30) | D22: =CEILING(D21+Margin,30) | E22: 最低＋余白を30秒単位で切り上げ。
A23: a_ready_now | B23: 現行ALBでのフロント応答時刻 | C23: =P_sec+B_fe | D23: =B_fe | E23: 現行間隔でも準備完了時刻は同じ。
A24: a_extra_now | B24: 現行ALBの追加 | C24: =IF(C23<=C9,I_alb_now,I_alb_now*H_alb_now) | D24: =IF(D23<=D9,I_alb_now,I_alb_now*H_alb_now) | E24: 既定30×5=150秒になりやすい。
A25: a_gmin_now | B25: A 現行ALBの最低猶予 | C25: =MAX(C23+C24,C20) | D25: =MAX(D23+D24,D20) | E25: 既定のままの並列構成。
A26: a_grec_now | B26: A 現行ALBの推奨猶予 | C26: =CEILING(C25+Margin,30) | D26: =CEILING(D25+Margin,30) | E26: 既定ALBのままなら、300秒では足りないことが多い。
A27: パターンB ADOT HEALTHY → バックエンド HEALTHY → フロント。要件を全部守る直列。
A28: b_be_start | B28: バックエンドのプロセス開始 | C28: =P_sec+B_adot+I_adot | D28: =B_adot+I_adot | E28: ADOTのHEALTHYのあと。
A29: b_be_ok | B29: バックエンドHEALTHY | C29: =C28+B_be+I_be | D29: =D28+B_be+I_be | E29: ここでフロントのプロセスが初めて開始する。
A30: b_fe_start | B30: フロントのプロセス開始 | C30: =C29 | D30: =D29 | E30: depends_on HEALTHY が解けた瞬間。startPeriodの終わりではない。
A31: b_ready | B31: フロントが応答できる | C31: =C30+B_fe | D31: =D30+B_fe | E31: フロント自身の起動予算のあと。
A32: b_extra | B32: ALB追加（直列なので通常は復帰パス） | C32: =IF(C31<=C8,I_alb,I_alb*H_alb) | D32: =IF(D31<=D8,I_alb,I_alb*H_alb) | E32: 登録が先頭で、フロントが遅いので、ほぼ必ず故障札からの復帰。
A33: b_alb | B33: ALBがhealthyになる最悪 | C33: =C31+C32 | D33: =D31+D32 | E33: パターンBの律速。
A34: b_gmin | B34: Bの最低猶予 | C34: =MAX(C33,C30+B_fe+I_fe,C29) | D34: =MAX(D33,D30+B_fe+I_fe,D29) | E34: ALB復帰とコンテナHEALTHYの遅い方。
A35: b_grec | B35: Bの推奨猶予 | C35: =CEILING(C34+Margin,30) | D35: =CEILING(D34+Margin,30) | E35: 直列を維持するならこの秒数。
A36: b_extra_now | B36: B 現行ALBの追加 | C36: =IF(C31<=C9,I_alb_now,I_alb_now*H_alb_now) | D36: =IF(D31<=D9,I_alb_now,I_alb_now*H_alb_now) | E36: 既定だと復帰だけで最大150秒。
A37: b_gmin_now | B37: B 現行ALBの最低猶予 | C37: =MAX(C31+C36,C30+B_fe+I_fe) | D37: =MAX(D31+D36,D30+B_fe+I_fe) | E37: 既定ALBの直列。
A38: b_grec_now | B38: B 現行ALBの推奨猶予 | C38: =CEILING(C37+Margin,30) | D38: =CEILING(D37+Margin,30) | E38: 最も長い組み合わせ。
A39: パターンC バックエンドだけADOTのHEALTHYを待つ。フロントは待たない。
A40: c_be_ok | B40: バックエンドHEALTHY | C40: =P_sec+B_adot+I_adot+B_be+I_be | D40: =B_adot+I_adot+B_be+I_be | E40: トレースの受け皿ができてから厨房が開く。
A41: c_ready | B41: フロントが応答できる | C41: =P_sec+B_fe | D41: =B_fe | E41: フロントの準備完了パスがバックエンドを呼ぶと、この仮定は崩れてBに近づく。
...

Sheet 09_300秒の現場
A1: 現行300秒の瞬間
A2: ALBの検査は300秒で始まりません。最初から叩いています。300秒で終わるのは、店長がその赤札を無視する時間です。
A4: 見ているもの | B4: 安全側（Pを含む） | C4: 取得後起算（P=0） | D4: 読み方
A5: 猶予の終わり | B5: =GraceNow | C5: =GraceNow | D5: この秒で、スケジューラは異常をタスク停止の材料にし始めます。
A6: B: ADOTがHEALTHY | B6: ='08_計算'!C28 | C6: ='08_計算'!D28 | D6: この時刻にバックエンドのプロセスが開始します。
A7: B: バックエンドHEALTHY＝フロント開始 | B7: ='08_計算'!C30 | C7: ='08_計算'!D30 | D7: startPeriodが210だからこの時刻、ではありません。検査が成功した時刻です。
A8: B: 300秒時点のフロント稼働秒 | B8: =MAX(0,GraceNow-'08_計算'!C30) | C8: =MAX(0,GraceNow-'08_計算'!D30) | D8: 0なら、フロントはまだプロセスが無い。
A9: B: フロントの残り起動予算 | B9: =MAX(0,B_fe-MAX(0,GraceNow-'08_計算'!C30)) | C9: =MAX(0,B_fe-MAX(0,GraceNow-'08_計算'!D30)) | D9: 210秒予算に対し、猶予終了時にまだ残っている起動。
A10: B: ALB healthy の最悪 | B10: ='08_計算'!C33 | C10: ='08_計算'!D33 | D10: ここまで猶予が無いと、復帰の連続成功の途中でタスクを止められ得る。
A11: B: 最低線までの不足 | B11: =MAX(0,'08_計算'!C34-GraceNow) | C11: =MAX(0,'08_計算'!D34-GraceNow) | D11: 0より大きいなら、現行猶予は直列の最低線より短い。
A12: C: バックエンドHEALTHY | B12: ='08_計算'!C40 | C12: ='08_計算'!D40 | D12: フロントは待たないので、ALBはフロント自身の起動だけを見る。
A13: C: ALB healthy の最悪 | B13: ='08_計算'!C43 | C13: ='08_計算'!D43 | D13: バックエンドのコンテナHEALTHYがこれより遅いなら、猶予はそちらに合わせる。
A14: A: ALB healthy の最悪（推奨ALB） | B14: ='08_計算'!C19 | C14: ='08_計算'!D19 | D14: 依存が無い現行形。推奨ALBなら取得後起算で300秒付近。
A15: A: 最低線（現行ALBのまま） | B15: ='08_計算'!C25 | C15: ='08_計算'!D25 | D15: 既定の健全しきい値5のままだと、並列でも300秒を超える。
A17: 取得後起算のパターンBでは、300秒のときバックエンドはすでにHEALTHYで、フロントは起動して数十秒です。相談の「バックはOK、フロントは立ち上げはじめ、案内人はもう見逃さない」と一致します。安全側では、300秒のときフロントのプロセス自体がまだ無いことまであり得ます。

Sheet 10_パターン比較
A1: パターン比較
A2: 同じ起動予算で、依存の引き方が猶予をどう変えるか。数値は01_結論と同じ式です。
A4: パターン | B4: 起動の順番 | C4: 守れること | D4: 払うもの
A5: A 並列 | B5: ADOT、CW、バック、フロントが同時にプロセス開始 | C5: 壁時計が一番短い。フロントのAPIリトライと、トレース送信側の再送があれば欠落も小さい。 | D5: 起動直後のトレースがADOTの準備前に捨てられる。フロントが厨房を呼ぶと失敗する。
A6: B 全直列 | B6: ADOT HEALTHY → バック HEALTHY → フロント | C6: 起動直後からトレースを受けられる。フロントのプロセスは厨房のAPIが検査成功したあとだけ動く。終了順は逆になり、フロント、バック、ADOTの順で止まる。 | D6: 猶予が最も長い。壊れたタスクの置き換えもその秒数まで遅れる。バックのstartTimeoutは120秒上限のため書けない。
A7: C 折衷 | B7: ADOT HEALTHY → バック。フロントは同時開始 | C7: トレースの受け皿を守る。フロントのALB時計はフロント自身の起動で済む。 | D7: フロントは厨房がHEALTHYになるまでAPI失敗を自分でやり直す。準備完了URLが厨房を呼ぶと、実質Bになる。
A8: D 分割 | B8: フロントのサービスとバックのサービス | C8: 時計が2つ。片方の遅い起動が、もう片方の猶予を食べない。 | D8: タスク間は localhost では話せない。Service Connect か内部ALB。depends_on はタスクを越えられない。
A9: E 短い実測 | B9: Bと同じ直列。起動予算だけ短い例 | C9: 直列そのものが悪いのではない、という確認用。 | D9: 本番予算が210秒のままでは、この行の短さは使えない。
A10: 縮めたstartPeriod | B10: 依存はBのまま。免責だけ短くする | C10: アプリが本当にその秒数で準備完了なら有効。 | D10: 210秒かかる日は、免責のあと失敗が積もってUNHEALTHY。HEALTHY待ちは解けず、フロントは起動しない。

Sheet 11_採用設定値
A1: 採用設定値
A2: コマンドのポートとパスは例です。イメージに curl や ps が無い場合は、そのイメージに入っている検査コマンドへ変えます。
A4: 対象 | B4: 項目 | C4: パターンB | D4: パターンC | E4: 単位または形 | F4: 下限 | G4: 上限 | H4: コマンドまたは条件 | I4: 補足
A5: ADOT | B5: essential | C5: true | D5: true | E5: 真偽 | F5: — | G5: — | H5: — | I5: true にするとコレクタ停止でタスク全体が止まる。トレースが黙って消える状態を残さない選択。
A6: ADOT | B6: dependsOn | C6: なし | D6: なし | E6: — | F6: — | G6: — | H6: 先頭で起動 | I6: 待つ側に書きます。待たれる側には書きません。
A7: ADOT | B7: interval | C7: 5 | D7: 5 | E7: 秒 | F7: 5 | G7: 300 | H7: ["CMD","/healthcheck"] | I7: 公式サンプルは interval 5、timeout 6、retries 5、startPeriod 1。timeout が interval 以上でもコンテナ検査は許可されます。
A8: ADOT | B8: timeout | C8: 2 | D8: 2 | E8: 秒 | F8: 2 | G8: 60 | H8: /healthcheck はローカルで即返す | I8: 2秒で足ります。ALBの「timeoutはintervalより短く」は、このコンテナ検査には適用されません。
A9: ADOT | B9: retries | C9: 5 | D9: 5 | E9: 回 | F9: 1 | G9: 10 | H9: 連続失敗でUNHEALTHY | I9: 成功に必要な回数は1回です。retries は失敗の回数です。
A10: ADOT | B10: startPeriod | C10: ='08_計算'!C10 | D10: ='08_計算'!C10 | E10: 秒 | F10: 0 | G10: 300 | H10: 失敗の免責 | I10: この間に成功すれば、すぐバックエンドを起動できます。60秒待ちません。
A11: ADOT | B11: startTimeout | C11: ='08_計算'!C14 | D11: ='08_計算'!C14 | E11: 秒 | F11: 2 | G11: 120 | H11: ADOTコンテナに書く | I11: この秒までにHEALTHYにならなければ、待っているバックエンドは起動を諦め、タスクはSTOPPEDになります。
A12: バックエンド | B12: essential | C12: true | D12: true | E12: 真偽 | F12: — | G12: — | H12: — | I12: API本体。
A13: バックエンド | B13: dependsOn | C13: ADOT HEALTHY | D13: ADOT HEALTHY | E13: 条件 | F13: — | G13: — | H13: condition HEALTHY | I13: START はプロセス生成だけを見ます。ポートが開く前にトレースを送ると捨てられます。
A14: バックエンド | B14: interval | C14: 10 | D14: 10 | E14: 秒 | F14: 5 | G14: 300 | H14: ["CMD-SHELL","curl -f http://127.0.0.1:8080/health || exit 1"] | I14: 8080 と /health は例。準備完了を返すURLにする。生存だけを返すURLだと、依存が早すぎる。
A15: バックエンド | B15: timeout | C15: 5 | D15: 5 | E15: 秒 | F15: 2 | G15: 60 | H15: 検査1回の上限 | I15: interval 10 より短い。
A16: バックエンド | B16: retries | C16: 3 | D16: 3 | E16: 回 | F16: 1 | G16: 10 | H16: 免責後の連続失敗 | I16: 既定3。
A17: バックエンド | B17: startPeriod | C17: ='08_計算'!C11 | D17: ='08_計算'!C11 | E17: 秒 | F17: 0 | G17: 300 | H17: 起動予算＋余白、上限300 | I17: プロセス開始から数える。タスク開始からではない。
A18: バックエンド | B18: startTimeout | C18: 空欄 | D18: 空欄 | E18: 秒 | F18: 2 | G18: 120 | H18: 書かない | I18: HEALTHYまでの最悪が120秒を超えるため。書くとフロントが必ず諦めます。未指定時の隠れた上限は公式ページに秒数がありません。試験デプロイで待ちきれることを確認します。
A19: フロント | B19: essential | C19: true | D19: true | E19: 真偽 | F19: — | G19: — | H19: — | I19: ALBのターゲット。
A20: フロント | B20: dependsOn | C20: バックエンド HEALTHY | D20: なし | E20: 条件 | F20: — | G20: — | H20: パターンBだけHEALTHY | I20: 終了時は逆順。フロントが止まってからバックエンドが止まる。
A21: フロント | B21: interval | C21: 10 | D21: 10 | E21: 秒 | F21: 5 | G21: 300 | H21: ["CMD-SHELL","curl -f http://127.0.0.1:3000/health || exit 1"] | I21: ポートは例。ALBと同じ準備完了の意味にする。
A22: フロント | B22: timeout | C22: 5 | D22: 5 | E22: 秒 | F22: 2 | G22: 60 | H22: 検査1回の上限
A23: フロント | B23: retries | C23: 3 | D23: 3 | E23: 回 | F23: 1 | G23: 10 | H23: 免責後の連続失敗
A24: フロント | B24: startPeriod | C24: ='08_計算'!C12 | D24: ='08_計算'!C12 | E24: 秒 | F24: 0 | G24: 300 | H24: フロントのプロセス開始から | I24: 直列の待ち時間はここには含まれない。待ちは相手のHEALTHYが担当する。
A25: フロント | B25: startTimeout | C25: 空欄 | D25: 空欄 | E25: 秒 | F25: 2 | G25: 120 | H25: 書かない | I25: バックエンド側の待ちが上限を超える。
A26: CW Agent | B26: essential | C26: false | D26: false | E26: 真偽 | F26: — | G26: — | H26: — | I26: false なので、検査失敗でもタスクヘルスには入らない。タスクは動き続ける。
A27: CW Agent | B27: dependsOn | C27: なし | D27: なし | E27: — | F27: — | G27: — | H27: 書かない | I27: 起動順の外。ログドライバ awslogs は、このサイドカーを待たずにログを出せます。
A28: CW Agent | B28: interval | C28: 30 | D28: 30 | E28: 秒 | F28: 5 | G28: 300 | H28: ["CMD-SHELL","ps -eo args | grep -v grep | grep -q amazon-cloudwatch-agent || exit 1"] | I28: プロセス名はイメージで確認。ps が無いイメージではこのコマンドは失敗します。essential false なのでタスクは落ちませんが、UNHEALTHY表示は残ります。
A29: CW Agent | B29: timeout | C29: 5 | D29: 5 | E29: 秒 | F29: 2 | G29: 60
A30: CW Agent | B30: retries | C30: 3 | D30: 3 | E30: 回 | F30: 1 | G30: 10
A31: CW Agent | B31: startPeriod | C31: ='08_計算'!C13 | D31: ='08_計算'!C13 | E31: 秒 | F31: 0 | G31: 300 | I31: 直列時間に加算しない。
A32: CW Agent | B32: startTimeout | C32: 空欄 | D32: 空欄 | E32: — | F32: 2 | G32: 120
A33: ECSサービス | B33: healthCheckGracePeriodSeconds | C33: ='08_計算'!C35 | D33: ='08_計算'!C45 | E33: 秒 | F33: 0 | G33: 2147483647 | H33: B列の隣はパターンBの安全側推奨。C列の隣はパターンC | I33: 既定0。変更しても新しいデプロイは自動では始まりません。
A34: ALB TG | B34: Interval | C34: 10 | D34: 10 | E34: 秒 | F34: 5 | G34: 300 | H34: フロントのポート | I34: 既定30。
A35: ALB TG | B35: Timeout | C35: 5 | D35: 5 | E35: 秒 | F35: 2 | G35: 120 | H35: 間隔より短く保つ | I35: 既定5。Classic ELBのAPIは timeout < interval を明記。推奨値はその関係を満たす。
A36: ALB TG | B36: Healthy threshold | C36: 2 | D36: 2 | E36: 回 | F36: 2 | G36: 10 | H36: 故障札からの復帰 | I36: 新規登録のままなら成功1回でhealthy。既定5。
A37: ALB TG | B37: Unhealthy threshold | C37: 3 | D37: 3 | E37: 回 | F37: 2 | G37: 10 | H37: 故障札にする連続失敗 | I37: 既定2。
A38: ALB TG | B38: Path / Matcher | C38: 準備完了パス / 200 | D38: 同じ | E38: — | F38: — | G38: — | H38: 成功コードは200〜499で指定可。既定200 | I38: 13133はALBに向けません。
A39: ALB TG | B39: Slow start | C39: 0 | D39: 0 | E39: 秒 | F39: 0 | G39: 900 | H39: 0は無効。有効時は30〜900 | I39: healthy のあと流量を増やす機能。検査開始は遅らせません。
A40: ALB TG | B40: 登録解除の遅延 | C40: リクエストの最大時間に合わせる | D40: 同じ | E40: 秒 | F40: 0 | G40: 3600 | H40: 既定300 | I40: 閉店後に既存接続を送り出す時間。起動の猶予ではない。

Sheet 12_取り違え
A1: 12_取り違え
A2: 300秒と表示される隣の設定は、開店の時計ではありません。
A4: サービスの猶予
A5: 場所は ECS サービスの healthCheckGracePeriodSeconds です。既定は0です。開店から、店長が赤札を無視する時間です。今回伸ばすのはここです。
A6: 登録解除の遅延
A7: 場所はターゲットグループの属性 deregistration_delay.timeout_seconds です。既定は300秒、範囲は0〜3600秒です。店を閉めるとき、いま処理中のリクエストを送り出す時間です。デプロイの終盤で古いタスクが残る長さに効きます。起動の失敗を見逃す長さには効きません。
A8: 短時間のAPIなら120秒でも足りることが多いです。長時間のダウンロードやWebSocketがあるなら、その最大時間に合わせます。今回の起動問題の解として300のまま残しても、直列起動の失敗は防げません。
A9: アイドルタイムアウト
A10: ALBの無通信接続を切る秒数です。既定60秒、範囲は1〜4000秒です。リクエストの処理中ではなく、黙っている接続の話です。起動順とは別です。
A11: スロースタート
A12: ターゲットが healthy になったあと、流量を徐々に増やす秒数です。0で無効、有効なら30〜900秒です。ノックの開始は早まりも遅れもしません。準備完了前の赤札は解けません。
A13: Auto Scaling の300秒
... A18: retries は失敗が何回続いたら病気にするか、です。健全しきい値は、故障札の店を何回連続成功で案内先に戻すか、です。両方を「5回成功でOK」と読むと、起動時間の見積もりがずれます。コンテナがHEALTHYになる成功回数は1回です。

Sheet 13_チェックリスト
A1: 13_チェックリスト
A2: 値を入れる前と、入れたあとの確認です。
A4: 測る
A5: 1. いったん猶予を長め（たとえば900秒）にし、依存なしで1回デプロイする。タスクが途中で殺されない状態で、各コンテナの実時間を測る。
A6: 2. DescribeTasks で pullStartedAt、pullStoppedAt、startedAt を見る。P は取得の差。猶予の起点は、ターゲット登録時刻と startedAt の早い方に寄せる。
A7: 3. ADOT、バックエンド、フロントのそれぞれについて、プロセス開始から検査成功までの秒を B として 07_前提へ入れる。サイドカーがいるタスクで測る。
A8: 4. ターゲットグループの間隔、健全しきい値、不健全しきい値を 07_前提の現行ALBへ入れる。不明のままなら既定30、5、2のままにする。
A9: 選ぶ
A10: 5. フロントの準備完了URLがバックエンドを呼ぶなら、パターンCの短さは使わない。パターンBかDの式を見る。
A11: 6. トレースの再送がアプリに無いなら、バックエンドの depends_on は ADOT の HEALTHY のままにする。
A12: 7. フロントのプロセス自体を厨房のあとで起動する要件があるならパターンB。APIリトライで足りるならパターンC。
A13: 8. パターンBの推奨猶予をサービスへ入れる。startPeriodは計算シートの値のまま。バックエンドの startTimeout は空欄。ADOTの startTimeout は計算値。
... A24: 17. desiredCount 1 のフェイルオープンを許容しないなら、タスク数か minimumHealthyPercent を見直す。

Sheet 14_出典
A1: 14_出典
A2: 数値の根拠にした公開文書です。画面の現行値は、この環境のコンソールが優先します。
A4: ECS
A5: コンテナヘルスチェックの説明。startPeriod は失敗を retries に数えない猶予で、期間内の成功は直ちに healthy。https://docs.aws.amazon.com/AmazonECS/latest/developerguide/healthcheck.html
A6: HealthCheck API。interval 5〜300 既定30、timeout 2〜60 既定5、retries 1〜10 既定3、startPeriod 0〜300。Fargate はプラットフォーム 1.1.0 以降。https://docs.aws.amazon.com/AmazonECS/latest/APIReference/API_HealthCheck.html
A7: ContainerDependency。START、COMPLETE、SUCCESS、HEALTHY。HEALTHY は検査設定が必要で、確認は起動時だけ。https://docs.aws.amazon.com/AmazonECS/latest/APIReference/API_ContainerDependency.html
A8: ContainerDefinition の startTimeout。Fargate の有効値は 2〜120 秒。Linux プラットフォーム 1.3.0 以降。https://docs.aws.amazon.com/AmazonECS/latest/APIReference/API_ContainerDefinition.html
A9: Fargate のタスク定義パラメータ。startTimeout の最大は120秒、stopTimeout の最大は120秒、既定30秒。https://docs.aws.amazon.com/AmazonECS/latest/developerguide/task_definition_parameters.html
A10: healthCheckGracePeriodSeconds。ELB、VPC Lattice、コンテナ検査を、タスク開始後に無視する。最大 2,147,483,647 秒。既定0。desired 超過時の例外あり。変更は新デプロイを起動しない。
A11: ロードバランサー検査の最適化。新規ターゲットは成功1回で healthy。健全しきい値は unhealthy からの復帰だけ。既定の復帰例は30×5＝150秒。https://docs.aws.amazon.com/AmazonECS/latest/developerguide/load-balancer-healthcheck.html
A12: ALB
A13: ターゲットグループのヘルスチェック。間隔5〜300、タイムアウト2〜120、健全しきい値2〜10既定5、不健全しきい値2〜10既定2、成功コード200〜499。全ターゲット unhealthy のフェイルオープン。https://docs.aws.amazon.com/elasticloadbalancing/latest/application/target-group-health-checks.html
... A22: 登録時刻と猶予のゼロ地点が同一秒であるとは、公式が1文では書いていません。安全側を採用すれば、ゼロ地点が前でも後でも、見積もりが不足側に倒れにくくなります。
